<?xml version="1.0" ?>
<sdf version="1.6">
  <model name="inspection_robot">
    
    <!-- Base link (chassis) -->
    <link name="base_link">
      <pose>0 0 0.15 0 0 0</pose>
      <inertial>
        <mass>20.0</mass>
        <inertia>
          <ixx>0.4</ixx>
          <ixy>0</ixy>
          <ixz>0</ixz>
          <iyy>1.0</iyy>
          <iyz>0</iyz>
          <izz>1.2</izz>
        </inertia>
      </inertial>

      <!-- Chassis visual -->
      <visual name="chassis_visual">
        <geometry>
          <box>
            <size>1.0 0.6 0.3</size>
          </box>
        </geometry>
        <material>
          <ambient>0.2 0.2 0.8 1.0</ambient>
          <diffuse>0.2 0.2 0.8 1.0</diffuse>
          <specular>0.5 0.5 0.5 1.0</specular>
        </material>
      </visual>

      <!-- Chassis collision -->
      <collision name="chassis_collision">
        <geometry>
          <box>
            <size>1.0 0.6 0.3</size>
          </box>
        </geometry>
      </collision>

      <!-- GPS Sensor -->
      <sensor name="gps_sensor" type="navsat">
        <pose>0 0 0.2 0 0 0</pose>
        <always_on>true</always_on>
        <update_rate>10</update_rate>
        <topic>/mavros/global_position/global</topic>
        <navsat>
          <position_sensing>
            <horizontal>
              <noise type="gaussian">
                <mean>0.0</mean>
                <stddev>2e-4</stddev>
              </noise>
            </horizontal>
            <vertical>
              <noise type="gaussian">
                <mean>0.0</mean>
                <stddev>2e-4</stddev>
              </noise>
            </vertical>
          </position_sensing>
          <velocity_sensing>
            <horizontal>
              <noise type="gaussian">
                <mean>0.0</mean>
                <stddev>0.1</stddev>
              </noise>
            </horizontal>
            <vertical>
              <noise type="gaussian">
                <mean>0.0</mean>
                <stddev>0.1</stddev>
              </noise>
            </vertical>
          </velocity_sensing>
        </navsat>
      </sensor>

      <!-- IMU Sensor (for heading/orientation) -->
      <sensor name="imu_sensor" type="imu">
        <pose>0 0 0.2 0 0 0</pose>
        <always_on>true</always_on>
        <update_rate>100</update_rate>
        <topic>/imu/data</topic>
        <imu>
          <angular_velocity>
            <x>
              <noise type="gaussian">
                <mean>0.0</mean>
                <stddev>2e-4</stddev>
              </noise>
            </x>
            <y>
              <noise type="gaussian">
                <mean>0.0</mean>
                <stddev>2e-4</stddev>
              </noise>
            </y>
            <z>
              <noise type="gaussian">
                <mean>0.0</mean>
                <stddev>2e-4</stddev>
              </noise>
            </z>
          </angular_velocity>
          <linear_acceleration>
            <x>
              <noise type="gaussian">
                <mean>0.0</mean>
                <stddev>1.7e-2</stddev>
              </noise>
            </x>
            <y>
              <noise type="gaussian">
                <mean>0.0</mean>
                <stddev>1.7e-2</stddev>
              </noise>
            </y>
            <z>
              <noise type="gaussian">
                <mean>0.0</mean>
                <stddev>1.7e-2</stddev>
              </noise>
            </z>
          </linear_acceleration>
        </imu>
      </sensor>
    </link>

    <!-- LiDAR Link -->
    <link name="lidar_link">
      <pose>0.3 0 0.35 0 0 0</pose>
      <inertial>
        <mass>0.5</mass>
        <inertia>
          <ixx>0.001</ixx>
          <ixy>0</ixy>
          <ixz>0</ixz>
          <iyy>0.001</iyy>
          <iyz>0</iyz>
          <izz>0.001</izz>
        </inertia>
      </inertial>
      
      <!-- LiDAR Visual -->
      <visual name="lidar_visual">
        <geometry>
          <cylinder>
            <radius>0.05</radius>
            <length>0.07</length>
          </cylinder>
        </geometry>
        <material>
          <ambient>0.1 0.1 0.1 1.0</ambient>
          <diffuse>0.2 0.2 0.2 1.0</diffuse>
        </material>
      </visual>

      <!-- LiDAR Sensor - 3D point cloud -->
      <sensor name="velodyne" type="gpu_lidar">
        <pose>0 0 0.035 0 0 0</pose>
        <topic>lidar</topic>
        <always_on>1</always_on>
        <update_rate>10</update_rate>
        <visualize>true</visualize>
        <lidar>
          <scan>
            <horizontal>
              <samples>640</samples>
              <resolution>1</resolution>
              <min_angle>-3.14159</min_angle>
              <max_angle>3.14159</max_angle>
            </horizontal>
            <vertical>
              <samples>16</samples>
              <resolution>1</resolution>
              <min_angle>-0.261799</min_angle>
              <max_angle>0.261799</max_angle>
            </vertical>
          </scan>
          <range>
            <min>0.1</min>
            <max>30.0</max>
            <resolution>0.01</resolution>
          </range>
          <noise>
            <type>gaussian</type>
            <mean>0.0</mean>
            <stddev>0.01</stddev>
          </noise>
        </lidar>
        <ignition_frame_id>velodyne</ignition_frame_id>
      </sensor>
    </link>

    <!-- LiDAR Joint -->
    <joint name="lidar_joint" type="fixed">
      <parent>base_link</parent>
      <child>lidar_link</child>
    </joint>

    <!-- Front Left Wheel -->
    <link name="front_left_wheel">
      <pose>0.35 0.4 0.1 -1.5707 0 0</pose>
      <inertial>
        <mass>2.0</mass>
        <inertia>
          <ixx>0.01</ixx>
          <ixy>0</ixy>
          <ixz>0</ixz>
          <iyy>0.01</iyy>
          <iyz>0</iyz>
          <izz>0.01</izz>
        </inertia>
      </inertial>
      <visual name="visual">
        <geometry>
          <cylinder>
            <radius>0.1</radius>
            <length>0.08</length>
          </cylinder>
        </geometry>
        <material>
          <ambient>0.1 0.1 0.1 1.0</ambient>
          <diffuse>0.1 0.1 0.1 1.0</diffuse>
        </material>
      </visual>
      <collision name="collision">
        <geometry>
          <cylinder>
            <radius>0.1</radius>
            <length>0.08</length>
          </cylinder>
        </geometry>
        <surface>
          <friction>
            <ode>
              <mu>1.0</mu>
              <mu2>1.0</mu2>
            </ode>
          </friction>
        </surface>
      </collision>
    </link>

    <!-- Front Right Wheel -->
    <link name="front_right_wheel">
      <pose>0.35 -0.4 0.1 -1.5707 0 0</pose>
      <inertial>
        <mass>2.0</mass>
        <inertia>
          <ixx>0.01</ixx>
          <ixy>0</ixy>
          <ixz>0</ixz>
          <iyy>0.01</iyy>
          <iyz>0</iyz>
          <izz>0.01</izz>
        </inertia>
      </inertial>
      <visual name="visual">
        <geometry>
          <cylinder>
            <radius>0.1</radius>
            <length>0.08</length>
          </cylinder>
        </geometry>
        <material>
          <ambient>0.1 0.1 0.1 1.0</ambient>
          <diffuse>0.1 0.1 0.1 1.0</diffuse>
        </material>
      </visual>
      <collision name="collision">
        <geometry>
          <cylinder>
            <radius>0.1</radius>
            <length>0.08</length>
          </cylinder>
        </geometry>
        <surface>
          <friction>
            <ode>
              <mu>1.0</mu>
              <mu2>1.0</mu2>
            </ode>
          </friction>
        </surface>
      </collision>
    </link>

    <!-- Rear Left Wheel -->
    <link name="rear_left_wheel">
      <pose>-0.35 0.4 0.1 -1.5707 0 0</pose>
      <inertial>
        <mass>2.0</mass>
        <inertia>
          <ixx>0.01</ixx>
          <ixy>0</ixy>
          <ixz>0</ixz>
          <iyy>0.01</iyy>
          <iyz>0</iyz>
          <izz>0.01</izz>
        </inertia>
      </inertial>
      <visual name="visual">
        <geometry>
          <cylinder>
            <radius>0.1</radius>
            <length>0.08</length>
          </cylinder>
        </geometry>
        <material>
          <ambient>0.1 0.1 0.1 1.0</ambient>
          <diffuse>0.1 0.1 0.1 1.0</diffuse>
        </material>
      </visual>
      <collision name="collision">
        <geometry>
          <cylinder>
            <radius>0.1</radius>
            <length>0.08</length>
          </cylinder>
        </geometry>
        <surface>
          <friction>
            <ode>
              <mu>1.0</mu>
              <mu2>1.0</mu2>
            </ode>
          </friction>
        </surface>
      </collision>
    </link>

    <!-- Rear Right Wheel -->
    <link name="rear_right_wheel">
      <pose>-0.35 -0.4 0.1 -1.5707 0 0</pose>
      <inertial>
        <mass>2.0</mass>
        <inertia>
          <ixx>0.01</ixx>
          <ixy>0</ixy>
          <ixz>0</ixz>
          <iyy>0.01</iyy>
          <iyz>0</iyz>
          <izz>0.01</izz>
        </inertia>
      </inertial>
      <visual name="visual">
        <geometry>
          <cylinder>
            <radius>0.1</radius>
            <length>0.08</length>
          </cylinder>
        </geometry>
        <material>
          <ambient>0.1 0.1 0.1 1.0</ambient>
          <diffuse>0.1 0.1 0.1 1.0</diffuse>
        </material>
      </visual>
      <collision name="collision">
        <geometry>
          <cylinder>
            <radius>0.1</radius>
            <length>0.08</length>
          </cylinder>
        </geometry>
        <surface>
          <friction>
            <ode>
              <mu>1.0</mu>
              <mu2>1.0</mu2>
            </ode>
          </friction>
        </surface>
      </collision>
    </link>

    <!-- Wheel Joints -->
    <joint name="front_left_wheel_joint" type="revolute">
      <parent>base_link</parent>
      <child>front_left_wheel</child>
      <axis>
        <xyz>0 1 0</xyz>
        <limit>
          <lower>-1e16</lower>
          <upper>1e16</upper>
        </limit>
      </axis>
    </joint>

    <joint name="front_right_wheel_joint" type="revolute">
      <parent>base_link</parent>
      <child>front_right_wheel</child>
      <axis>
        <xyz>0 1 0</xyz>
        <limit>
          <lower>-1e16</lower>
          <upper>1e16</upper>
        </limit>
      </axis>
    </joint>

    <joint name="rear_left_wheel_joint" type="revolute">
      <parent>base_link</parent>
      <child>rear_left_wheel</child>
      <axis>
        <xyz>0 1 0</xyz>
        <limit>
          <lower>-1e16</lower>
          <upper>1e16</upper>
        </limit>
      </axis>
    </joint>

    <joint name="rear_right_wheel_joint" type="revolute">
      <parent>base_link</parent>
      <child>rear_right_wheel</child>
      <axis>
        <xyz>0 1 0</xyz>
        <limit>
          <lower>-1e16</lower>
          <upper>1e16</upper>
        </limit>
      </axis>
    </joint>

    <!-- Differential drive plugin (Fortress naming) -->
    <plugin filename="ignition-gazebo-diff-drive-system" name="ignition::gazebo::systems::DiffDrive">
      <left_joint>front_left_wheel_joint</left_joint>
      <left_joint>rear_left_wheel_joint</left_joint>
      <right_joint>front_right_wheel_joint</right_joint>
      <right_joint>rear_right_wheel_joint</right_joint>
      <wheel_separation>0.8</wheel_separation>
      <wheel_radius>0.1</wheel_radius>
      <max_linear_acceleration>5.0</max_linear_acceleration>
      <min_linear_acceleration>-5.0</min_linear_acceleration>
      <max_angular_acceleration>3.0</max_angular_acceleration>
      <min_angular_acceleration>-3.0</min_angular_acceleration>
      <max_linear_velocity>10.0</max_linear_velocity>
      <min_linear_velocity>-10.0</min_linear_velocity>
      <max_angular_velocity>2.0</max_angular_velocity>
      <min_angular_velocity>-2.0</min_angular_velocity>
      <topic>/cmd_vel</topic>
      <odom_topic>/odom</odom_topic>
      <frame_id>odom</frame_id>
      <child_frame_id>base_link</child_frame_id>
    </plugin>

  </model>
</sdf>
